[Tue Jun 24 00:11:59.675184 2014] [:error] [pid 31800] [remote 187.151.44.200:37155] mod_wsgi (pid=31800): Exception occurred processing WSGI script '/var/www/djalton/djalton/wsgi.py'.
[Tue Jun 24 00:11:59.675321 2014] [:error] [pid 31800] [remote 187.151.44.200:37155] Traceback (most recent call last):
[Tue Jun 24 00:11:59.675347 2014] [:error] [pid 31800] [remote 187.151.44.200:37155]   File "/usr/local/lib/python2.7/dist-packages/django/core/handlers/wsgi.py", line 187, in __call__
[Tue Jun 24 00:11:59.689704 2014] [:error] [pid 31800] [remote 187.151.44.200:37155]     self.load_middleware()
[Tue Jun 24 00:11:59.689728 2014] [:error] [pid 31800] [remote 187.151.44.200:37155]   File "/usr/local/lib/python2.7/dist-packages/django/core/handlers/base.py", line 44, in load_middleware
[Tue Jun 24 00:11:59.690335 2014] [:error] [pid 31800] [remote 187.151.44.200:37155]     for middleware_path in settings.MIDDLEWARE_CLASSES:
[Tue Jun 24 00:11:59.690356 2014] [:error] [pid 31800] [remote 187.151.44.200:37155]   File "/usr/local/lib/python2.7/dist-packages/django/conf/__init__.py", line 54, in __getattr__
[Tue Jun 24 00:11:59.699337 2014] [:error] [pid 31800] [remote 187.151.44.200:37155]     self._setup(name)
[Tue Jun 24 00:11:59.699374 2014] [:error] [pid 31800] [remote 187.151.44.200:37155]   File "/usr/local/lib/python2.7/dist-packages/django/conf/__init__.py", line 49, in _setup
[Tue Jun 24 00:11:59.699423 2014] [:error] [pid 31800] [remote 187.151.44.200:37155]     self._wrapped = Settings(settings_module)
[Tue Jun 24 00:11:59.699450 2014] [:error] [pid 31800] [remote 187.151.44.200:37155]   File "/usr/local/lib/python2.7/dist-packages/django/conf/__init__.py", line 132, in __init__
[Tue Jun 24 00:11:59.699491 2014] [:error] [pid 31800] [remote 187.151.44.200:37155]     % (self.SETTINGS_MODULE, e)
[Tue Jun 24 00:11:59.699534 2014] [:error] [pid 31800] [remote 187.151.44.200:37155] ImportError: Could not import settings 'djalton.settings' (Is it on sys.path? Is there an import error in the settings file?): No module named djalton.settings
[Tue Jun 24 00:12:00.458609 2014] [:error] [pid 31799] [remote 187.151.44.200:37155] mod_wsgi (pid=31799): Exception occurred processing WSGI script '/var/www/djalton/djalton/wsgi.py'.
[Tue Jun 24 00:12:00.458680 2014] [:error] [pid 31799] [remote 187.151.44.200:37155] Traceback (most recent call last):
[Tue Jun 24 00:12:00.458708 2014] [:error] [pid 31799] [remote 187.151.44.200:37155]   File "/usr/local/lib/python2.7/dist-packages/django/core/handlers/wsgi.py", line 187, in __call__
[Tue Jun 24 00:12:00.458850 2014] [:error] [pid 31799] [remote 187.151.44.200:37155]     self.load_middleware()
[Tue Jun 24 00:12:00.458869 2014] [:error] [pid 31799] [remote 187.151.44.200:37155]   File "/usr/local/lib/python2.7/dist-packages/django/core/handlers/base.py", line 44, in load_middleware
[Tue Jun 24 00:12:00.459027 2014] [:error] [pid 31799] [remote 187.151.44.200:37155]     for middleware_path in settings.MIDDLEWARE_CLASSES:
[Tue Jun 24 00:12:00.459047 2014] [:error] [pid 31799] [remote 187.151.44.200:37155]   File "/usr/local/lib/python2.7/dist-packages/django/conf/__init__.py", line 54, in __getattr__
[Tue Jun 24 00:12:00.459157 2014] [:error] [pid 31799] [remote 187.151.44.200:37155]     self._setup(name)
[Tue Jun 24 00:12:00.459174 2014] [:error] [pid 31799] [remote 187.151.44.200:37155]   File "/usr/local/lib/python2.7/dist-packages/django/conf/__init__.py", line 49, in _setup
[Tue Jun 24 00:12:00.459199 2014] [:error] [pid 31799] [remote 187.151.44.200:37155]     self._wrapped = Settings(settings_module)
[Tue Jun 24 00:12:00.459212 2014] [:error] [pid 31799] [remote 187.151.44.200:37155]   File "/usr/local/lib/python2.7/dist-packages/django/conf/__init__.py", line 132, in __init__
[Tue Jun 24 00:12:00.459231 2014] [:error] [pid 31799] [remote 187.151.44.200:37155]     % (self.SETTINGS_MODULE, e)
[Tue Jun 24 00:12:00.459254 2014] [:error] [pid 31799] [remote 187.151.44.200:37155] ImportError: Could not import settings 'djalton.settings' (Is it on sys.path? Is there an import error in the settings file?): No module named djalton.settings
[Tue Jun 24 00:12:00.766731 2014] [:error] [pid 31800] [remote 187.151.44.200:6669] mod_wsgi (pid=31800): Exception occurred processing WSGI script '/var/www/djalton/djalton/wsgi.py'.
[Tue Jun 24 00:12:00.766785 2014] [:error] [pid 31800] [remote 187.151.44.200:6669] Traceback (most recent call last):
[Tue Jun 24 00:12:00.766818 2014] [:error] [pid 31800] [remote 187.151.44.200:6669]   File "/usr/local/lib/python2.7/dist-packages/django/core/handlers/wsgi.py", line 187, in __call__
[Tue Jun 24 00:12:00.766913 2014] [:error] [pid 31800] [remote 187.151.44.200:6669]     self.load_middleware()
[Tue Jun 24 00:12:00.766968 2014] [:error] [pid 31800] [remote 187.151.44.200:6669]   File "/usr/local/lib/python2.7/dist-packages/django/core/handlers/base.py", line 44, in load_middleware
[Tue Jun 24 00:12:00.767029 2014] [:error] [pid 31800] [remote 187.151.44.200:6669]     for middleware_path in settings.MIDDLEWARE_CLASSES:
[Tue Jun 24 00:12:00.767155 2014] [:error] [pid 31800] [remote 187.151.44.200:6669]   File "/usr/local/lib/python2.7/dist-packages/django/conf/__init__.py", line 54, in __getattr__
[Tue Jun 24 00:12:00.767182 2014] [:error] [pid 31800] [remote 187.151.44.200:6669]     self._setup(name)
[Tue Jun 24 00:12:00.767204 2014] [:error] [pid 31800] [remote 187.151.44.200:6669]   File "/usr/local/lib/python2.7/dist-packages/django/conf/__init__.py", line 49, in _setup
[Tue Jun 24 00:12:00.767390 2014] [:error] [pid 31800] [remote 187.151.44.200:6669]     self._wrapped = Settings(settings_module)
[Tue Jun 24 00:12:00.767445 2014] [:error] [pid 31800] [remote 187.151.44.200:6669]   File "/usr/local/lib/python2.7/dist-packages/django/conf/__init__.py", line 132, in __init__
[Tue Jun 24 00:12:00.767481 2014] [:error] [pid 31800] [remote 187.151.44.200:6669]     % (self.SETTINGS_MODULE, e)
[Tue Jun 24 00:12:00.767601 2014] [:error] [pid 31800] [remote 187.151.44.200:6669] ImportError: Could not import settings 'djalton.settings' (Is it on sys.path? Is there an import error in the settings file?): No module named djalton.settings
[Tue Jun 24 00:15:06.274965 2014] [:error] [pid 31799] [remote 187.151.44.200:6669] mod_wsgi (pid=31799): Exception occurred processing WSGI script '/var/www/djalton/djalton/wsgi.py'.
[Tue Jun 24 00:15:06.275038 2014] [:error] [pid 31799] [remote 187.151.44.200:6669] Traceback (most recent call last):
[Tue Jun 24 00:15:06.275073 2014] [:error] [pid 31799] [remote 187.151.44.200:6669]   File "/usr/local/lib/python2.7/dist-packages/django/core/handlers/wsgi.py", line 187, in __call__
[Tue Jun 24 00:15:06.275131 2014] [:error] [pid 31799] [remote 187.151.44.200:6669]     self.load_middleware()
[Tue Jun 24 00:15:06.275150 2014] [:error] [pid 31799] [remote 187.151.44.200:6669]   File "/usr/local/lib/python2.7/dist-packages/django/core/handlers/base.py", line 44, in load_middleware
[Tue Jun 24 00:15:06.275175 2014] [:error] [pid 31799] [remote 187.151.44.200:6669]     for middleware_path in settings.MIDDLEWARE_CLASSES:
[Tue Jun 24 00:15:06.275189 2014] [:error] [pid 31799] [remote 187.151.44.200:6669]   File "/usr/local/lib/python2.7/dist-packages/django/conf/__init__.py", line 54, in __getattr__
[Tue Jun 24 00:15:06.275210 2014] [:error] [pid 31799] [remote 187.151.44.200:6669]     self._setup(name)
[Tue Jun 24 00:15:06.275223 2014] [:error] [pid 31799] [remote 187.151.44.200:6669]   File "/usr/local/lib/python2.7/dist-packages/django/conf/__init__.py", line 49, in _setup
[Tue Jun 24 00:15:06.275243 2014] [:error] [pid 31799] [remote 187.151.44.200:6669]     self._wrapped = Settings(settings_module)
[Tue Jun 24 00:15:06.275255 2014] [:error] [pid 31799] [remote 187.151.44.200:6669]   File "/usr/local/lib/python2.7/dist-packages/django/conf/__init__.py", line 132, in __init__
[Tue Jun 24 00:15:06.275275 2014] [:error] [pid 31799] [remote 187.151.44.200:6669]     % (self.SETTINGS_MODULE, e)
[Tue Jun 24 00:15:06.275302 2014] [:error] [pid 31799] [remote 187.151.44.200:6669] ImportError: Could not import settings 'djalton.settings' (Is it on sys.path? Is there an import error in the settings file?): No module named djalton.settings
[Tue Jun 24 00:15:06.778366 2014] [:error] [pid 31800] [remote 187.151.44.200:6669] mod_wsgi (pid=31800): Exception occurred processing WSGI script '/var/www/djalton/djalton/wsgi.py'.
[Tue Jun 24 00:15:06.778461 2014] [:error] [pid 31800] [remote 187.151.44.200:6669] Traceback (most recent call last):
[Tue Jun 24 00:15:06.778499 2014] [:error] [pid 31800] [remote 187.151.44.200:6669]   File "/usr/local/lib/python2.7/dist-packages/django/core/handlers/wsgi.py", line 187, in __call__
[Tue Jun 24 00:15:06.778553 2014] [:error] [pid 31800] [remote 187.151.44.200:6669]     self.load_middleware()
[Tue Jun 24 00:15:06.778572 2014] [:error] [pid 31800] [remote 187.151.44.200:6669]   File "/usr/local/lib/python2.7/dist-packages/django/core/handlers/base.py", line 44, in load_middleware
[Tue Jun 24 00:15:06.778602 2014] [:error] [pid 31800] [remote 187.151.44.200:6669]     for middleware_path in settings.MIDDLEWARE_CLASSES:
[Tue Jun 24 00:15:06.778620 2014] [:error] [pid 31800] [remote 187.151.44.200:6669]   File "/usr/local/lib/python2.7/dist-packages/django/conf/__init__.py", line 54, in __getattr__
[Tue Jun 24 00:15:06.778650 2014] [:error] [pid 31800] [remote 187.151.44.200:6669]     self._setup(name)
[Tue Jun 24 00:15:06.778667 2014] [:error] [pid 31800] [remote 187.151.44.200:6669]   File "/usr/local/lib/python2.7/dist-packages/django/conf/__init__.py", line 49, in _setup
[Tue Jun 24 00:15:06.778695 2014] [:error] [pid 31800] [remote 187.151.44.200:6669]     self._wrapped = Settings(settings_module)
[Tue Jun 24 00:15:06.778712 2014] [:error] [pid 31800] [remote 187.151.44.200:6669]   File "/usr/local/lib/python2.7/dist-packages/django/conf/__init__.py", line 132, in __init__
[Tue Jun 24 00:15:06.778740 2014] [:error] [pid 31800] [remote 187.151.44.200:6669]     % (self.SETTINGS_MODULE, e)
[Tue Jun 24 00:15:06.778774 2014] [:error] [pid 31800] [remote 187.151.44.200:6669] ImportError: Could not import settings 'djalton.settings' (Is it on sys.path? Is there an import error in the settings file?): No module named djalton.settings
[Tue Jun 24 00:15:07.078331 2014] [:error] [pid 31800] [remote 187.151.44.200:30243] mod_wsgi (pid=31800): Exception occurred processing WSGI script '/var/www/djalton/djalton/wsgi.py'.
[Tue Jun 24 00:15:07.078397 2014] [:error] [pid 31800] [remote 187.151.44.200:30243] Traceback (most recent call last):
[Tue Jun 24 00:15:07.078434 2014] [:error] [pid 31800] [remote 187.151.44.200:30243]   File "/usr/local/lib/python2.7/dist-packages/django/core/handlers/wsgi.py", line 187, in __call__
[Tue Jun 24 00:15:07.078487 2014] [:error] [pid 31800] [remote 187.151.44.200:30243]     self.load_middleware()
[Tue Jun 24 00:15:07.078508 2014] [:error] [pid 31800] [remote 187.151.44.200:30243]   File "/usr/local/lib/python2.7/dist-packages/django/core/handlers/base.py", line 44, in load_middleware
[Tue Jun 24 00:15:07.078541 2014] [:error] [pid 31800] [remote 187.151.44.200:30243]     for middleware_path in settings.MIDDLEWARE_CLASSES:
[Tue Jun 24 00:15:07.078560 2014] [:error] [pid 31800] [remote 187.151.44.200:30243]   File "/usr/local/lib/python2.7/dist-packages/django/conf/__init__.py", line 54, in __getattr__
[Tue Jun 24 00:15:07.078592 2014] [:error] [pid 31800] [remote 187.151.44.200:30243]     self._setup(name)
[Tue Jun 24 00:15:07.078610 2014] [:error] [pid 31800] [remote 187.151.44.200:30243]   File "/usr/local/lib/python2.7/dist-packages/django/conf/__init__.py", line 49, in _setup
[Tue Jun 24 00:15:07.078640 2014] [:error] [pid 31800] [remote 187.151.44.200:30243]     self._wrapped = Settings(settings_module)
[Tue Jun 24 00:15:07.078658 2014] [:error] [pid 31800] [remote 187.151.44.200:30243]   File "/usr/local/lib/python2.7/dist-packages/django/conf/__init__.py", line 132, in __init__
[Tue Jun 24 00:15:07.078688 2014] [:error] [pid 31800] [remote 187.151.44.200:30243]     % (self.SETTINGS_MODULE, e)
[Tue Jun 24 00:15:07.078723 2014] [:error] [pid 31800] [remote 187.151.44.200:30243] ImportError: Could not import settings 'djalton.settings' (Is it on sys.path? Is there an import error in the settings file?): No module named djalton.settings
[Tue Jun 24 00:15:20.238540 2014] [:error] [pid 31800] [remote 187.151.44.200:30243] mod_wsgi (pid=31800): Exception occurred processing WSGI script '/var/www/djalton/djalton/wsgi.py'.
[Tue Jun 24 00:15:20.238761 2014] [:error] [pid 31800] [remote 187.151.44.200:30243] Traceback (most recent call last):
[Tue Jun 24 00:15:20.238795 2014] [:error] [pid 31800] [remote 187.151.44.200:30243]   File "/usr/local/lib/python2.7/dist-packages/django/core/handlers/wsgi.py", line 187, in __call__
[Tue Jun 24 00:15:20.238837 2014] [:error] [pid 31800] [remote 187.151.44.200:30243]     self.load_middleware()
[Tue Jun 24 00:15:20.238851 2014] [:error] [pid 31800] [remote 187.151.44.200:30243]   File "/usr/local/lib/python2.7/dist-packages/django/core/handlers/base.py", line 44, in load_middleware
[Tue Jun 24 00:15:20.239029 2014] [:error] [pid 31800] [remote 187.151.44.200:30243]     for middleware_path in settings.MIDDLEWARE_CLASSES:
[Tue Jun 24 00:15:20.239134 2014] [:error] [pid 31800] [remote 187.151.44.200:30243]   File "/usr/local/lib/python2.7/dist-packages/django/conf/__init__.py", line 54, in __getattr__
[Tue Jun 24 00:15:20.239169 2014] [:error] [pid 31800] [remote 187.151.44.200:30243]     self._setup(name)
[Tue Jun 24 00:15:20.239184 2014] [:error] [pid 31800] [remote 187.151.44.200:30243]   File "/usr/local/lib/python2.7/dist-packages/django/conf/__init__.py", line 49, in _setup
[Tue Jun 24 00:15:20.239284 2014] [:error] [pid 31800] [remote 187.151.44.200:30243]     self._wrapped = Settings(settings_module)
[Tue Jun 24 00:15:20.239361 2014] [:error] [pid 31800] [remote 187.151.44.200:30243]   File "/usr/local/lib/python2.7/dist-packages/django/conf/__init__.py", line 132, in __init__
[Tue Jun 24 00:15:20.239447 2014] [:error] [pid 31800] [remote 187.151.44.200:30243]     % (self.SETTINGS_MODULE, e)
[Tue Jun 24 00:15:20.239478 2014] [:error] [pid 31800] [remote 187.151.44.200:30243] ImportError: Could not import settings 'djalton.settings' (Is it on sys.path? Is there an import error in the settings file?): No module named djalton.settings
[Tue Jun 24 00:15:20.671258 2014] [:error] [pid 31800] [remote 187.151.44.200:6669] mod_wsgi (pid=31800): Exception occurred processing WSGI script '/var/www/djalton/djalton/wsgi.py'.
[Tue Jun 24 00:15:20.671334 2014] [:error] [pid 31800] [remote 187.151.44.200:6669] Traceback (most recent call last):
[Tue Jun 24 00:15:20.671375 2014] [:error] [pid 31800] [remote 187.151.44.200:6669]   File "/usr/local/lib/python2.7/dist-packages/django/core/handlers/wsgi.py", line 187, in __call__
[Tue Jun 24 00:15:20.671436 2014] [:error] [pid 31800] [remote 187.151.44.200:6669]     self.load_middleware()
[Tue Jun 24 00:15:20.671465 2014] [:error] [pid 31800] [remote 187.151.44.200:6669]   File "/usr/local/lib/python2.7/dist-packages/django/core/handlers/base.py", line 44, in load_middleware
[Tue Jun 24 00:15:20.671515 2014] [:error] [pid 31800] [remote 187.151.44.200:6669]     for middleware_path in settings.MIDDLEWARE_CLASSES:
[Tue Jun 24 00:15:20.671542 2014] [:error] [pid 31800] [remote 187.151.44.200:6669]   File "/usr/local/lib/python2.7/dist-packages/django/conf/__init__.py", line 54, in __getattr__
[Tue Jun 24 00:15:20.671591 2014] [:error] [pid 31800] [remote 187.151.44.200:6669]     self._setup(name)
[Tue Jun 24 00:15:20.671621 2014] [:error] [pid 31800] [remote 187.151.44.200:6669]   File "/usr/local/lib/python2.7/dist-packages/django/conf/__init__.py", line 49, in _setup
[Tue Jun 24 00:15:20.671667 2014] [:error] [pid 31800] [remote 187.151.44.200:6669]     self._wrapped = Settings(settings_module)
[Tue Jun 24 00:15:20.671698 2014] [:error] [pid 31800] [remote 187.151.44.200:6669]   File "/usr/local/lib/python2.7/dist-packages/django/conf/__init__.py", line 132, in __init__
[Tue Jun 24 00:15:20.671737 2014] [:error] [pid 31800] [remote 187.151.44.200:6669]     % (self.SETTINGS_MODULE, e)
[Tue Jun 24 00:15:20.671768 2014] [:error] [pid 31800] [remote 187.151.44.200:6669] ImportError: Could not import settings 'djalton.settings' (Is it on sys.path? Is there an import error in the settings file?): No module named djalton.settings
[Tue Jun 24 00:15:20.968438 2014] [:error] [pid 31800] [remote 187.151.44.200:6669] mod_wsgi (pid=31800): Exception occurred processing WSGI script '/var/www/djalton/djalton/wsgi.py'.
[Tue Jun 24 00:15:20.968501 2014] [:error] [pid 31800] [remote 187.151.44.200:6669] Traceback (most recent call last):
[Tue Jun 24 00:15:20.968537 2014] [:error] [pid 31800] [remote 187.151.44.200:6669]   File "/usr/local/lib/python2.7/dist-packages/django/core/handlers/wsgi.py", line 187, in __call__
[Tue Jun 24 00:15:20.968639 2014] [:error] [pid 31800] [remote 187.151.44.200:6669]     self.load_middleware()
[Tue Jun 24 00:15:20.968666 2014] [:error] [pid 31800] [remote 187.151.44.200:6669]   File "/usr/local/lib/python2.7/dist-packages/django/core/handlers/base.py", line 44, in load_middleware
[Tue Jun 24 00:15:20.968696 2014] [:error] [pid 31800] [remote 187.151.44.200:6669]     for middleware_path in settings.MIDDLEWARE_CLASSES:
[Tue Jun 24 00:15:20.968713 2014] [:error] [pid 31800] [remote 187.151.44.200:6669]   File "/usr/local/lib/python2.7/dist-packages/django/conf/__init__.py", line 54, in __getattr__
[Tue Jun 24 00:15:20.968747 2014] [:error] [pid 31800] [remote 187.151.44.200:6669]     self._setup(name)
[Tue Jun 24 00:15:20.968769 2014] [:error] [pid 31800] [remote 187.151.44.200:6669]   File "/usr/local/lib/python2.7/dist-packages/django/conf/__init__.py", line 49, in _setup
[Tue Jun 24 00:15:20.968876 2014] [:error] [pid 31800] [remote 187.151.44.200:6669]     self._wrapped = Settings(settings_module)
[Tue Jun 24 00:15:20.968906 2014] [:error] [pid 31800] [remote 187.151.44.200:6669]   File "/usr/local/lib/python2.7/dist-packages/django/conf/__init__.py", line 132, in __init__
[Tue Jun 24 00:15:20.968944 2014] [:error] [pid 31800] [remote 187.151.44.200:6669]     % (self.SETTINGS_MODULE, e)
[Tue Jun 24 00:15:20.968982 2014] [:error] [pid 31800] [remote 187.151.44.200:6669] ImportError: Could not import settings 'djalton.settings' (Is it on sys.path? Is there an import error in the settings file?): No module named djalton.settings
[Tue Jun 24 00:15:35.145885 2014] [:error] [pid 31800] [remote 187.151.44.200:30243] mod_wsgi (pid=31800): Exception occurred processing WSGI script '/var/www/djalton/djalton/wsgi.py'.
[Tue Jun 24 00:15:35.145943 2014] [:error] [pid 31800] [remote 187.151.44.200:30243] Traceback (most recent call last):
[Tue Jun 24 00:15:35.146048 2014] [:error] [pid 31800] [remote 187.151.44.200:30243]   File "/usr/local/lib/python2.7/dist-packages/django/core/handlers/wsgi.py", line 187, in __call__
[Tue Jun 24 00:15:35.146096 2014] [:error] [pid 31800] [remote 187.151.44.200:30243]     self.load_middleware()
[Tue Jun 24 00:15:35.146113 2014] [:error] [pid 31800] [remote 187.151.44.200:30243]   File "/usr/local/lib/python2.7/dist-packages/django/core/handlers/base.py", line 44, in load_middleware
[Tue Jun 24 00:15:35.146141 2014] [:error] [pid 31800] [remote 187.151.44.200:30243]     for middleware_path in settings.MIDDLEWARE_CLASSES:
[Tue Jun 24 00:15:35.146155 2014] [:error] [pid 31800] [remote 187.151.44.200:30243]   File "/usr/local/lib/python2.7/dist-packages/django/conf/__init__.py", line 54, in __getattr__
[Tue Jun 24 00:15:35.146175 2014] [:error] [pid 31800] [remote 187.151.44.200:30243]     self._setup(name)
[Tue Jun 24 00:15:35.146188 2014] [:error] [pid 31800] [remote 187.151.44.200:30243]   File "/usr/local/lib/python2.7/dist-packages/django/conf/__init__.py", line 49, in _setup
[Tue Jun 24 00:15:35.146207 2014] [:error] [pid 31800] [remote 187.151.44.200:30243]     self._wrapped = Settings(settings_module)
[Tue Jun 24 00:15:35.146219 2014] [:error] [pid 31800] [remote 187.151.44.200:30243]   File "/usr/local/lib/python2.7/dist-packages/django/conf/__init__.py", line 132, in __init__
[Tue Jun 24 00:15:35.146239 2014] [:error] [pid 31800] [remote 187.151.44.200:30243]     % (self.SETTINGS_MODULE, e)
[Tue Jun 24 00:15:35.146264 2014] [:error] [pid 31800] [remote 187.151.44.200:30243] ImportError: Could not import settings 'djalton.settings' (Is it on sys.path? Is there an import error in the settings file?): No module named djalton.settings
[Tue Jun 24 00:15:35.639670 2014] [:error] [pid 31799] [remote 187.151.44.200:6669] mod_wsgi (pid=31799): Exception occurred processing WSGI script '/var/www/djalton/djalton/wsgi.py'.
[Tue Jun 24 00:15:35.639722 2014] [:error] [pid 31799] [remote 187.151.44.200:6669] Traceback (most recent call last):
[Tue Jun 24 00:15:35.639751 2014] [:error] [pid 31799] [remote 187.151.44.200:6669]   File "/usr/local/lib/python2.7/dist-packages/django/core/handlers/wsgi.py", line 187, in __call__
[Tue Jun 24 00:15:35.639792 2014] [:error] [pid 31799] [remote 187.151.44.200:6669]     self.load_middleware()
[Tue Jun 24 00:15:35.639806 2014] [:error] [pid 31799] [remote 187.151.44.200:6669]   File "/usr/local/lib/python2.7/dist-packages/django/core/handlers/base.py", line 44, in load_middleware
[Tue Jun 24 00:15:35.639828 2014] [:error] [pid 31799] [remote 187.151.44.200:6669]     for middleware_path in settings.MIDDLEWARE_CLASSES:
[Tue Jun 24 00:15:35.639962 2014] [:error] [pid 31799] [remote 187.151.44.200:6669]   File "/usr/local/lib/python2.7/dist-packages/django/conf/__init__.py", line 54, in __getattr__
[Tue Jun 24 00:15:35.639996 2014] [:error] [pid 31799] [remote 187.151.44.200:6669]     self._setup(name)
[Tue Jun 24 00:15:35.640009 2014] [:error] [pid 31799] [remote 187.151.44.200:6669]   File "/usr/local/lib/python2.7/dist-packages/django/conf/__init__.py", line 49, in _setup
[Tue Jun 24 00:15:35.640029 2014] [:error] [pid 31799] [remote 187.151.44.200:6669]     self._wrapped = Settings(settings_module)
[Tue Jun 24 00:15:35.640042 2014] [:error] [pid 31799] [remote 187.151.44.200:6669]   File "/usr/local/lib/python2.7/dist-packages/django/conf/__init__.py", line 132, in __init__
[Tue Jun 24 00:15:35.640061 2014] [:error] [pid 31799] [remote 187.151.44.200:6669]     % (self.SETTINGS_MODULE, e)
[Tue Jun 24 00:15:35.640086 2014] [:error] [pid 31799] [remote 187.151.44.200:6669] ImportError: Could not import settings 'djalton.settings' (Is it on sys.path? Is there an import error in the settings file?): No module named djalton.settings
[Tue Jun 24 00:15:35.967350 2014] [:error] [pid 31799] [remote 187.151.44.200:30243] mod_wsgi (pid=31799): Exception occurred processing WSGI script '/var/www/djalton/djalton/wsgi.py'.
[Tue Jun 24 00:15:35.967404 2014] [:error] [pid 31799] [remote 187.151.44.200:30243] Traceback (most recent call last):
[Tue Jun 24 00:15:35.967433 2014] [:error] [pid 31799] [remote 187.151.44.200:30243]   File "/usr/local/lib/python2.7/dist-packages/django/core/handlers/wsgi.py", line 187, in __call__
[Tue Jun 24 00:15:35.967474 2014] [:error] [pid 31799] [remote 187.151.44.200:30243]     self.load_middleware()
[Tue Jun 24 00:15:35.967488 2014] [:error] [pid 31799] [remote 187.151.44.200:30243]   File "/usr/local/lib/python2.7/dist-packages/django/core/handlers/base.py", line 44, in load_middleware
[Tue Jun 24 00:15:35.967510 2014] [:error] [pid 31799] [remote 187.151.44.200:30243]     for middleware_path in settings.MIDDLEWARE_CLASSES:
[Tue Jun 24 00:15:35.967522 2014] [:error] [pid 31799] [remote 187.151.44.200:30243]   File "/usr/local/lib/python2.7/dist-packages/django/conf/__init__.py", line 54, in __getattr__
[Tue Jun 24 00:15:35.967543 2014] [:error] [pid 31799] [remote 187.151.44.200:30243]     self._setup(name)
[Tue Jun 24 00:15:35.967555 2014] [:error] [pid 31799] [remote 187.151.44.200:30243]   File "/usr/local/lib/python2.7/dist-packages/django/conf/__init__.py", line 49, in _setup
[Tue Jun 24 00:15:35.967574 2014] [:error] [pid 31799] [remote 187.151.44.200:30243]     self._wrapped = Settings(settings_module)
[Tue Jun 24 00:15:35.967586 2014] [:error] [pid 31799] [remote 187.151.44.200:30243]   File "/usr/local/lib/python2.7/dist-packages/django/conf/__init__.py", line 132, in __init__
[Tue Jun 24 00:15:35.967604 2014] [:error] [pid 31799] [remote 187.151.44.200:30243]     % (self.SETTINGS_MODULE, e)
[Tue Jun 24 00:15:35.967629 2014] [:error] [pid 31799] [remote 187.151.44.200:30243] ImportError: Could not import settings 'djalton.settings' (Is it on sys.path? Is there an import error in the settings file?): No module named djalton.settings
[Tue Jun 24 00:23:25.586423 2014] [:error] [pid 31973] [remote 187.151.44.200:2089] mod_wsgi (pid=31973): Exception occurred processing WSGI script '/var/www/djalton/djalton/wsgi.py'.
[Tue Jun 24 00:23:25.586502 2014] [:error] [pid 31973] [remote 187.151.44.200:2089] Traceback (most recent call last):
[Tue Jun 24 00:23:25.586528 2014] [:error] [pid 31973] [remote 187.151.44.200:2089]   File "/usr/local/lib/python2.7/dist-packages/django/core/handlers/wsgi.py", line 187, in __call__
[Tue Jun 24 00:23:25.586664 2014] [:error] [pid 31973] [remote 187.151.44.200:2089]     self.load_middleware()
[Tue Jun 24 00:23:25.586683 2014] [:error] [pid 31973] [remote 187.151.44.200:2089]   File "/usr/local/lib/python2.7/dist-packages/django/core/handlers/base.py", line 44, in load_middleware
[Tue Jun 24 00:23:25.586833 2014] [:error] [pid 31973] [remote 187.151.44.200:2089]     for middleware_path in settings.MIDDLEWARE_CLASSES:
[Tue Jun 24 00:23:25.586853 2014] [:error] [pid 31973] [remote 187.151.44.200:2089]   File "/usr/local/lib/python2.7/dist-packages/django/conf/__init__.py", line 54, in __getattr__
[Tue Jun 24 00:23:25.586963 2014] [:error] [pid 31973] [remote 187.151.44.200:2089]     self._setup(name)
[Tue Jun 24 00:23:25.586982 2014] [:error] [pid 31973] [remote 187.151.44.200:2089]   File "/usr/local/lib/python2.7/dist-packages/django/conf/__init__.py", line 49, in _setup
[Tue Jun 24 00:23:25.587007 2014] [:error] [pid 31973] [remote 187.151.44.200:2089]     self._wrapped = Settings(settings_module)
[Tue Jun 24 00:23:25.587020 2014] [:error] [pid 31973] [remote 187.151.44.200:2089]   File "/usr/local/lib/python2.7/dist-packages/django/conf/__init__.py", line 132, in __init__
[Tue Jun 24 00:23:25.587041 2014] [:error] [pid 31973] [remote 187.151.44.200:2089]     % (self.SETTINGS_MODULE, e)
[Tue Jun 24 00:23:25.587065 2014] [:error] [pid 31973] [remote 187.151.44.200:2089] ImportError: Could not import settings 'djalton.settings' (Is it on sys.path? Is there an import error in the settings file?): No module named djalton.settings
[Tue Jun 24 00:23:26.370316 2014] [:error] [pid 31972] [remote 187.151.44.200:2089] mod_wsgi (pid=31972): Exception occurred processing WSGI script '/var/www/djalton/djalton/wsgi.py'.
[Tue Jun 24 00:23:26.370391 2014] [:error] [pid 31972] [remote 187.151.44.200:2089] Traceback (most recent call last):
[Tue Jun 24 00:23:26.370420 2014] [:error] [pid 31972] [remote 187.151.44.200:2089]   File "/usr/local/lib/python2.7/dist-packages/django/core/handlers/wsgi.py", line 187, in __call__
[Tue Jun 24 00:23:26.370564 2014] [:error] [pid 31972] [remote 187.151.44.200:2089]     self.load_middleware()
[Tue Jun 24 00:23:26.370583 2014] [:error] [pid 31972] [remote 187.151.44.200:2089]   File "/usr/local/lib/python2.7/dist-packages/django/core/handlers/base.py", line 44, in load_middleware
[Tue Jun 24 00:23:26.370736 2014] [:error] [pid 31972] [remote 187.151.44.200:2089]     for middleware_path in settings.MIDDLEWARE_CLASSES:
[Tue Jun 24 00:23:26.370755 2014] [:error] [pid 31972] [remote 187.151.44.200:2089]   File "/usr/local/lib/python2.7/dist-packages/django/conf/__init__.py", line 54, in __getattr__
[Tue Jun 24 00:23:26.370865 2014] [:error] [pid 31972] [remote 187.151.44.200:2089]     self._setup(name)
[Tue Jun 24 00:23:26.370891 2014] [:error] [pid 31972] [remote 187.151.44.200:2089]   File "/usr/local/lib/python2.7/dist-packages/django/conf/__init__.py", line 49, in _setup
[Tue Jun 24 00:23:26.370918 2014] [:error] [pid 31972] [remote 187.151.44.200:2089]     self._wrapped = Settings(settings_module)
[Tue Jun 24 00:23:26.370932 2014] [:error] [pid 31972] [remote 187.151.44.200:2089]   File "/usr/local/lib/python2.7/dist-packages/django/conf/__init__.py", line 132, in __init__
[Tue Jun 24 00:23:26.370953 2014] [:error] [pid 31972] [remote 187.151.44.200:2089]     % (self.SETTINGS_MODULE, e)
[Tue Jun 24 00:23:26.370994 2014] [:error] [pid 31972] [remote 187.151.44.200:2089] ImportError: Could not import settings 'djalton.settings' (Is it on sys.path? Is there an import error in the settings file?): No module named djalton.settings
[Tue Jun 24 00:23:26.665530 2014] [:error] [pid 31972] [remote 187.151.44.200:60712] mod_wsgi (pid=31972): Exception occurred processing WSGI script '/var/www/djalton/djalton/wsgi.py'.
[Tue Jun 24 00:23:26.665591 2014] [:error] [pid 31972] [remote 187.151.44.200:60712] Traceback (most recent call last):
[Tue Jun 24 00:23:26.665641 2014] [:error] [pid 31972] [remote 187.151.44.200:60712]   File "/usr/local/lib/python2.7/dist-packages/django/core/handlers/wsgi.py", line 187, in __call__
[Tue Jun 24 00:23:26.665701 2014] [:error] [pid 31972] [remote 187.151.44.200:60712]     self.load_middleware()
[Tue Jun 24 00:23:26.665731 2014] [:error] [pid 31972] [remote 187.151.44.200:60712]   File "/usr/local/lib/python2.7/dist-packages/django/core/handlers/base.py", line 44, in load_middleware
[Tue Jun 24 00:23:26.665778 2014] [:error] [pid 31972] [remote 187.151.44.200:60712]     for middleware_path in settings.MIDDLEWARE_CLASSES:
[Tue Jun 24 00:23:26.665805 2014] [:error] [pid 31972] [remote 187.151.44.200:60712]   File "/usr/local/lib/python2.7/dist-packages/django/conf/__init__.py", line 54, in __getattr__
[Tue Jun 24 00:23:26.665846 2014] [:error] [pid 31972] [remote 187.151.44.200:60712]     self._setup(name)
[Tue Jun 24 00:23:26.665870 2014] [:error] [pid 31972] [remote 187.151.44.200:60712]   File "/usr/local/lib/python2.7/dist-packages/django/conf/__init__.py", line 49, in _setup
[Tue Jun 24 00:23:26.665910 2014] [:error] [pid 31972] [remote 187.151.44.200:60712]     self._wrapped = Settings(settings_module)
[Tue Jun 24 00:23:26.665935 2014] [:error] [pid 31972] [remote 187.151.44.200:60712]   File "/usr/local/lib/python2.7/dist-packages/django/conf/__init__.py", line 132, in __init__
[Tue Jun 24 00:23:26.665974 2014] [:error] [pid 31972] [remote 187.151.44.200:60712]     % (self.SETTINGS_MODULE, e)
[Tue Jun 24 00:23:26.666016 2014] [:error] [pid 31972] [remote 187.151.44.200:60712] ImportError: Could not import settings 'djalton.settings' (Is it on sys.path? Is there an import error in the settings file?): No module named djalton.settings
[Tue Jun 24 00:43:58.573549 2014] [:error] [pid 32358] [remote 187.151.44.200:21329] mod_wsgi (pid=32358): Exception occurred processing WSGI script '/var/www/djalton/djalton/wsgi.py'.
[Tue Jun 24 00:43:58.573640 2014] [:error] [pid 32358] [remote 187.151.44.200:21329] Traceback (most recent call last):
[Tue Jun 24 00:43:58.573679 2014] [:error] [pid 32358] [remote 187.151.44.200:21329]   File "/var/www/djalton/djalton/wsgi.py", line 31, in application
[Tue Jun 24 00:43:58.573775 2014] [:error] [pid 32358] [remote 187.151.44.200:21329]     return _application(environ, start_response)
[Tue Jun 24 00:43:58.573797 2014] [:error] [pid 32358] [remote 187.151.44.200:21329]   File "/usr/local/lib/python2.7/dist-packages/django/core/handlers/wsgi.py", line 187, in __call__
[Tue Jun 24 00:43:58.573947 2014] [:error] [pid 32358] [remote 187.151.44.200:21329]     self.load_middleware()
[Tue Jun 24 00:43:58.574006 2014] [:error] [pid 32358] [remote 187.151.44.200:21329]   File "/usr/local/lib/python2.7/dist-packages/django/core/handlers/base.py", line 44, in load_middleware
[Tue Jun 24 00:43:58.574177 2014] [:error] [pid 32358] [remote 187.151.44.200:21329]     for middleware_path in settings.MIDDLEWARE_CLASSES:
[Tue Jun 24 00:43:58.574198 2014] [:error] [pid 32358] [remote 187.151.44.200:21329]   File "/usr/local/lib/python2.7/dist-packages/django/conf/__init__.py", line 54, in __getattr__
[Tue Jun 24 00:43:58.574304 2014] [:error] [pid 32358] [remote 187.151.44.200:21329]     self._setup(name)
[Tue Jun 24 00:43:58.574322 2014] [:error] [pid 32358] [remote 187.151.44.200:21329]   File "/usr/local/lib/python2.7/dist-packages/django/conf/__init__.py", line 49, in _setup
[Tue Jun 24 00:43:58.574346 2014] [:error] [pid 32358] [remote 187.151.44.200:21329]     self._wrapped = Settings(settings_module)
[Tue Jun 24 00:43:58.574367 2014] [:error] [pid 32358] [remote 187.151.44.200:21329]   File "/usr/local/lib/python2.7/dist-packages/django/conf/__init__.py", line 128, in __init__
[Tue Jun 24 00:43:58.574389 2014] [:error] [pid 32358] [remote 187.151.44.200:21329]     mod = importlib.import_module(self.SETTINGS_MODULE)
[Tue Jun 24 00:43:58.574401 2014] [:error] [pid 32358] [remote 187.151.44.200:21329]   File "/usr/local/lib/python2.7/dist-packages/django/utils/importlib.py", line 40, in import_module
[Tue Jun 24 00:43:58.578945 2014] [:error] [pid 32358] [remote 187.151.44.200:21329]     __import__(name)
[Tue Jun 24 00:43:58.579009 2014] [:error] [pid 32358] [remote 187.151.44.200:21329]   File "/var/www/djalton/djalton/settings.py", line 99
[Tue Jun 24 00:43:58.579020 2014] [:error] [pid 32358] [remote 187.151.44.200:21329]     ADMIN_MEDIA_PREFIX = '/static/admin/'
[Tue Jun 24 00:43:58.579027 2014] [:error] [pid 32358] [remote 187.151.44.200:21329]                        ^
[Tue Jun 24 00:43:58.579033 2014] [:error] [pid 32358] [remote 187.151.44.200:21329] SyntaxError: invalid syntax
[Tue Jun 24 00:43:59.057637 2014] [:error] [pid 32358] [remote 187.151.44.200:56378] mod_wsgi (pid=32358): Exception occurred processing WSGI script '/var/www/djalton/djalton/wsgi.py'.
[Tue Jun 24 00:43:59.058429 2014] [:error] [pid 32358] [remote 187.151.44.200:56378] Traceback (most recent call last):
[Tue Jun 24 00:43:59.058481 2014] [:error] [pid 32358] [remote 187.151.44.200:56378]   File "/var/www/djalton/djalton/wsgi.py", line 31, in application
[Tue Jun 24 00:43:59.058837 2014] [:error] [pid 32358] [remote 187.151.44.200:56378]     return _application(environ, start_response)
[Tue Jun 24 00:43:59.058955 2014] [:error] [pid 32358] [remote 187.151.44.200:56378]   File "/usr/local/lib/python2.7/dist-packages/django/core/handlers/wsgi.py", line 187, in __call__
[Tue Jun 24 00:43:59.059003 2014] [:error] [pid 32358] [remote 187.151.44.200:56378]     self.load_middleware()
[Tue Jun 24 00:43:59.059026 2014] [:error] [pid 32358] [remote 187.151.44.200:56378]   File "/usr/local/lib/python2.7/dist-packages/django/core/handlers/base.py", line 44, in load_middleware
[Tue Jun 24 00:43:59.059062 2014] [:error] [pid 32358] [remote 187.151.44.200:56378]     for middleware_path in settings.MIDDLEWARE_CLASSES:
[Tue Jun 24 00:43:59.059089 2014] [:error] [pid 32358] [remote 187.151.44.200:56378]   File "/usr/local/lib/python2.7/dist-packages/django/conf/__init__.py", line 54, in __getattr__
[Tue Jun 24 00:43:59.059152 2014] [:error] [pid 32358] [remote 187.151.44.200:56378]     self._setup(name)
[Tue Jun 24 00:43:59.059179 2014] [:error] [pid 32358] [remote 187.151.44.200:56378]   File "/usr/local/lib/python2.7/dist-packages/django/conf/__init__.py", line 49, in _setup
[Tue Jun 24 00:43:59.059218 2014] [:error] [pid 32358] [remote 187.151.44.200:56378]     self._wrapped = Settings(settings_module)
[Tue Jun 24 00:43:59.059243 2014] [:error] [pid 32358] [remote 187.151.44.200:56378]   File "/usr/local/lib/python2.7/dist-packages/django/conf/__init__.py", line 128, in __init__
[Tue Jun 24 00:43:59.059281 2014] [:error] [pid 32358] [remote 187.151.44.200:56378]     mod = importlib.import_module(self.SETTINGS_MODULE)
[Tue Jun 24 00:43:59.059307 2014] [:error] [pid 32358] [remote 187.151.44.200:56378]   File "/usr/local/lib/python2.7/dist-packages/django/utils/importlib.py", line 40, in import_module
[Tue Jun 24 00:43:59.059349 2014] [:error] [pid 32358] [remote 187.151.44.200:56378]     __import__(name)
[Tue Jun 24 00:43:59.059428 2014] [:error] [pid 32358] [remote 187.151.44.200:56378]   File "/var/www/djalton/djalton/settings.py", line 99
[Tue Jun 24 00:43:59.059446 2014] [:error] [pid 32358] [remote 187.151.44.200:56378]     ADMIN_MEDIA_PREFIX = '/static/admin/'
[Tue Jun 24 00:43:59.059459 2014] [:error] [pid 32358] [remote 187.151.44.200:56378]                        ^
[Tue Jun 24 00:43:59.059470 2014] [:error] [pid 32358] [remote 187.151.44.200:56378] SyntaxError: invalid syntax
[Tue Jun 24 00:43:59.648789 2014] [:error] [pid 32357] [remote 187.151.44.200:21329] mod_wsgi (pid=32357): Exception occurred processing WSGI script '/var/www/djalton/djalton/wsgi.py'.
[Tue Jun 24 00:43:59.648868 2014] [:error] [pid 32357] [remote 187.151.44.200:21329] Traceback (most recent call last):
[Tue Jun 24 00:43:59.648899 2014] [:error] [pid 32357] [remote 187.151.44.200:21329]   File "/var/www/djalton/djalton/wsgi.py", line 31, in application
[Tue Jun 24 00:43:59.648998 2014] [:error] [pid 32357] [remote 187.151.44.200:21329]     return _application(environ, start_response)
[Tue Jun 24 00:43:59.649030 2014] [:error] [pid 32357] [remote 187.151.44.200:21329]   File "/usr/local/lib/python2.7/dist-packages/django/core/handlers/wsgi.py", line 187, in __call__
[Tue Jun 24 00:43:59.649149 2014] [:error] [pid 32357] [remote 187.151.44.200:21329]     self.load_middleware()
[Tue Jun 24 00:43:59.649168 2014] [:error] [pid 32357] [remote 187.151.44.200:21329]   File "/usr/local/lib/python2.7/dist-packages/django/core/handlers/base.py", line 44, in load_middleware
[Tue Jun 24 00:43:59.649322 2014] [:error] [pid 32357] [remote 187.151.44.200:21329]     for middleware_path in settings.MIDDLEWARE_CLASSES:
[Tue Jun 24 00:43:59.649341 2014] [:error] [pid 32357] [remote 187.151.44.200:21329]   File "/usr/local/lib/python2.7/dist-packages/django/conf/__init__.py", line 54, in __getattr__
[Tue Jun 24 00:43:59.649446 2014] [:error] [pid 32357] [remote 187.151.44.200:21329]     self._setup(name)
[Tue Jun 24 00:43:59.649464 2014] [:error] [pid 32357] [remote 187.151.44.200:21329]   File "/usr/local/lib/python2.7/dist-packages/django/conf/__init__.py", line 49, in _setup
[Tue Jun 24 00:43:59.649488 2014] [:error] [pid 32357] [remote 187.151.44.200:21329]     self._wrapped = Settings(settings_module)
[Tue Jun 24 00:43:59.649501 2014] [:error] [pid 32357] [remote 187.151.44.200:21329]   File "/usr/local/lib/python2.7/dist-packages/django/conf/__init__.py", line 128, in __init__
[Tue Jun 24 00:43:59.649521 2014] [:error] [pid 32357] [remote 187.151.44.200:21329]     mod = importlib.import_module(self.SETTINGS_MODULE)
[Tue Jun 24 00:43:59.649534 2014] [:error] [pid 32357] [remote 187.151.44.200:21329]   File "/usr/local/lib/python2.7/dist-packages/django/utils/importlib.py", line 40, in import_module
[Tue Jun 24 00:43:59.649591 2014] [:error] [pid 32357] [remote 187.151.44.200:21329]     __import__(name)
[Tue Jun 24 00:43:59.649645 2014] [:error] [pid 32357] [remote 187.151.44.200:21329]   File "/var/www/djalton/djalton/settings.py", line 99
[Tue Jun 24 00:43:59.649655 2014] [:error] [pid 32357] [remote 187.151.44.200:21329]     ADMIN_MEDIA_PREFIX = '/static/admin/'
[Tue Jun 24 00:43:59.649662 2014] [:error] [pid 32357] [remote 187.151.44.200:21329]                        ^
[Tue Jun 24 00:43:59.649668 2014] [:error] [pid 32357] [remote 187.151.44.200:21329] SyntaxError: invalid syntax
[Tue Jun 24 05:08:00.186070 2014] [:error] [pid 32559] /usr/local/lib/python2.7/dist-packages/sorl/thumbnail/helpers.py:5: DeprecationWarning: django.utils.simplejson is deprecated; use json instead.
[Tue Jun 24 05:08:00.186126 2014] [:error] [pid 32559]   from django.utils import simplejson
[Tue Jun 24 05:08:00.186132 2014] [:error] [pid 32559] 
[Tue Jun 24 05:08:01.148856 2014] [:error] [pid 32560] /usr/local/lib/python2.7/dist-packages/sorl/thumbnail/helpers.py:5: DeprecationWarning: django.utils.simplejson is deprecated; use json instead.
[Tue Jun 24 05:08:01.148905 2014] [:error] [pid 32560]   from django.utils import simplejson
[Tue Jun 24 05:08:01.148911 2014] [:error] [pid 32560] 
[Tue Jun 24 05:20:27.363495 2014] [:error] [pid 318] /usr/local/lib/python2.7/dist-packages/sorl/thumbnail/helpers.py:5: DeprecationWarning: django.utils.simplejson is deprecated; use json instead.
[Tue Jun 24 05:20:27.363557 2014] [:error] [pid 318]   from django.utils import simplejson
[Tue Jun 24 05:20:27.363562 2014] [:error] [pid 318] 
[Tue Jun 24 05:20:28.187552 2014] [:error] [pid 319] /usr/local/lib/python2.7/dist-packages/sorl/thumbnail/helpers.py:5: DeprecationWarning: django.utils.simplejson is deprecated; use json instead.
[Tue Jun 24 05:20:28.187620 2014] [:error] [pid 319]   from django.utils import simplejson
[Tue Jun 24 05:20:28.187625 2014] [:error] [pid 319] 
[Tue Jun 24 05:26:19.847107 2014] [:error] [pid 474] /usr/local/lib/python2.7/dist-packages/sorl/thumbnail/helpers.py:5: DeprecationWarning: django.utils.simplejson is deprecated; use json instead.
[Tue Jun 24 05:26:19.847172 2014] [:error] [pid 474]   from django.utils import simplejson
[Tue Jun 24 05:26:19.847185 2014] [:error] [pid 474] 
[Tue Jun 24 05:26:20.746152 2014] [:error] [pid 473] /usr/local/lib/python2.7/dist-packages/sorl/thumbnail/helpers.py:5: DeprecationWarning: django.utils.simplejson is deprecated; use json instead.
[Tue Jun 24 05:26:20.746203 2014] [:error] [pid 473]   from django.utils import simplejson
[Tue Jun 24 05:26:20.746208 2014] [:error] [pid 473] 
[Tue Jun 24 05:28:09.893061 2014] [:error] [pid 609] /usr/local/lib/python2.7/dist-packages/sorl/thumbnail/helpers.py:5: DeprecationWarning: django.utils.simplejson is deprecated; use json instead.
[Tue Jun 24 05:28:09.893124 2014] [:error] [pid 609]   from django.utils import simplejson
[Tue Jun 24 05:28:09.893129 2014] [:error] [pid 609] 
[Tue Jun 24 05:28:11.175399 2014] [:error] [pid 608] /usr/local/lib/python2.7/dist-packages/sorl/thumbnail/helpers.py:5: DeprecationWarning: django.utils.simplejson is deprecated; use json instead.
[Tue Jun 24 05:28:11.175448 2014] [:error] [pid 608]   from django.utils import simplejson
[Tue Jun 24 05:28:11.175454 2014] [:error] [pid 608] 
[Wed Jun 25 01:31:28.365989 2014] [:error] [pid 4043] /usr/local/lib/python2.7/dist-packages/sorl/thumbnail/helpers.py:5: DeprecationWarning: django.utils.simplejson is deprecated; use json instead.
[Wed Jun 25 01:31:28.366047 2014] [:error] [pid 4043]   from django.utils import simplejson
[Wed Jun 25 01:31:28.366053 2014] [:error] [pid 4043] 
[Wed Jun 25 01:31:33.068853 2014] [:error] [pid 4042] /usr/local/lib/python2.7/dist-packages/sorl/thumbnail/helpers.py:5: DeprecationWarning: django.utils.simplejson is deprecated; use json instead.
[Wed Jun 25 01:31:33.068911 2014] [:error] [pid 4042]   from django.utils import simplejson
[Wed Jun 25 01:31:33.068917 2014] [:error] [pid 4042] 
[Wed Jun 25 01:33:09.551731 2014] [:error] [pid 4173] /usr/local/lib/python2.7/dist-packages/sorl/thumbnail/helpers.py:5: DeprecationWarning: django.utils.simplejson is deprecated; use json instead.
[Wed Jun 25 01:33:09.551790 2014] [:error] [pid 4173]   from django.utils import simplejson
[Wed Jun 25 01:33:09.551795 2014] [:error] [pid 4173] 
[Wed Jun 25 01:33:11.551043 2014] [:error] [pid 4174] /usr/local/lib/python2.7/dist-packages/sorl/thumbnail/helpers.py:5: DeprecationWarning: django.utils.simplejson is deprecated; use json instead.
[Wed Jun 25 01:33:11.551100 2014] [:error] [pid 4174]   from django.utils import simplejson
[Wed Jun 25 01:33:11.551105 2014] [:error] [pid 4174] 
[Wed Jun 25 01:35:39.747308 2014] [:error] [pid 4309] /usr/local/lib/python2.7/dist-packages/sorl/thumbnail/helpers.py:5: DeprecationWarning: django.utils.simplejson is deprecated; use json instead.
[Wed Jun 25 01:35:39.747364 2014] [:error] [pid 4309]   from django.utils import simplejson
[Wed Jun 25 01:35:39.747370 2014] [:error] [pid 4309] 
[Wed Jun 25 01:35:41.075723 2014] [:error] [pid 4310] /usr/local/lib/python2.7/dist-packages/sorl/thumbnail/helpers.py:5: DeprecationWarning: django.utils.simplejson is deprecated; use json instead.
[Wed Jun 25 01:35:41.075776 2014] [:error] [pid 4310]   from django.utils import simplejson
[Wed Jun 25 01:35:41.075781 2014] [:error] [pid 4310] 
[Wed Jun 25 02:03:11.483583 2014] [:error] [pid 4569] /usr/local/lib/python2.7/dist-packages/sorl/thumbnail/helpers.py:5: DeprecationWarning: django.utils.simplejson is deprecated; use json instead.
[Wed Jun 25 02:03:11.483640 2014] [:error] [pid 4569]   from django.utils import simplejson
[Wed Jun 25 02:03:11.483646 2014] [:error] [pid 4569] 
[Wed Jun 25 02:03:12.553526 2014] [:error] [pid 4568] /usr/local/lib/python2.7/dist-packages/sorl/thumbnail/helpers.py:5: DeprecationWarning: django.utils.simplejson is deprecated; use json instead.
[Wed Jun 25 02:03:12.553590 2014] [:error] [pid 4568]   from django.utils import simplejson
[Wed Jun 25 02:03:12.553596 2014] [:error] [pid 4568] 
[Wed Jun 25 02:46:14.575163 2014] [:error] [pid 4849] /usr/local/lib/python2.7/dist-packages/sorl/thumbnail/helpers.py:5: DeprecationWarning: django.utils.simplejson is deprecated; use json instead.
[Wed Jun 25 02:46:14.575233 2014] [:error] [pid 4849]   from django.utils import simplejson
[Wed Jun 25 02:46:14.575239 2014] [:error] [pid 4849] 
[Wed Jun 25 02:46:15.471585 2014] [:error] [pid 4848] /usr/local/lib/python2.7/dist-packages/sorl/thumbnail/helpers.py:5: DeprecationWarning: django.utils.simplejson is deprecated; use json instead.
[Wed Jun 25 02:46:15.471636 2014] [:error] [pid 4848]   from django.utils import simplejson
[Wed Jun 25 02:46:15.471641 2014] [:error] [pid 4848] 
[Wed Jun 25 02:52:49.287370 2014] [:error] [pid 5034] /usr/local/lib/python2.7/dist-packages/sorl/thumbnail/helpers.py:5: DeprecationWarning: django.utils.simplejson is deprecated; use json instead.
[Wed Jun 25 02:52:49.287437 2014] [:error] [pid 5034]   from django.utils import simplejson
[Wed Jun 25 02:52:49.287443 2014] [:error] [pid 5034] 
[Wed Jun 25 02:52:50.388604 2014] [:error] [pid 5033] /usr/local/lib/python2.7/dist-packages/sorl/thumbnail/helpers.py:5: DeprecationWarning: django.utils.simplejson is deprecated; use json instead.
[Wed Jun 25 02:52:50.388670 2014] [:error] [pid 5033]   from django.utils import simplejson
[Wed Jun 25 02:52:50.388676 2014] [:error] [pid 5033] 
[Wed Jun 25 03:23:16.081072 2014] [:error] [pid 5273] /usr/local/lib/python2.7/dist-packages/sorl/thumbnail/helpers.py:5: DeprecationWarning: django.utils.simplejson is deprecated; use json instead.
[Wed Jun 25 03:23:16.081129 2014] [:error] [pid 5273]   from django.utils import simplejson
[Wed Jun 25 03:23:16.081134 2014] [:error] [pid 5273] 
[Wed Jun 25 03:23:16.981402 2014] [:error] [pid 5274] /usr/local/lib/python2.7/dist-packages/sorl/thumbnail/helpers.py:5: DeprecationWarning: django.utils.simplejson is deprecated; use json instead.
[Wed Jun 25 03:23:16.981454 2014] [:error] [pid 5274]   from django.utils import simplejson
[Wed Jun 25 03:23:16.981460 2014] [:error] [pid 5274] 
[Wed Jun 25 03:25:36.675409 2014] [:error] [pid 5408] /usr/local/lib/python2.7/dist-packages/sorl/thumbnail/helpers.py:5: DeprecationWarning: django.utils.simplejson is deprecated; use json instead.
[Wed Jun 25 03:25:36.675466 2014] [:error] [pid 5408]   from django.utils import simplejson
[Wed Jun 25 03:25:36.675472 2014] [:error] [pid 5408] 
[Wed Jun 25 03:25:38.261442 2014] [:error] [pid 5409] /usr/local/lib/python2.7/dist-packages/sorl/thumbnail/helpers.py:5: DeprecationWarning: django.utils.simplejson is deprecated; use json instead.
[Wed Jun 25 03:25:38.261496 2014] [:error] [pid 5409]   from django.utils import simplejson
[Wed Jun 25 03:25:38.261501 2014] [:error] [pid 5409] 
[Wed Jun 25 03:28:03.355612 2014] [:error] [pid 5545] /usr/local/lib/python2.7/dist-packages/sorl/thumbnail/helpers.py:5: DeprecationWarning: django.utils.simplejson is deprecated; use json instead.
[Wed Jun 25 03:28:03.355669 2014] [:error] [pid 5545]   from django.utils import simplejson
[Wed Jun 25 03:28:03.355675 2014] [:error] [pid 5545] 
[Wed Jun 25 03:28:04.366452 2014] [:error] [pid 5544] /usr/local/lib/python2.7/dist-packages/sorl/thumbnail/helpers.py:5: DeprecationWarning: django.utils.simplejson is deprecated; use json instead.
[Wed Jun 25 03:28:04.366503 2014] [:error] [pid 5544]   from django.utils import simplejson
[Wed Jun 25 03:28:04.366508 2014] [:error] [pid 5544] 
[Wed Jun 25 03:28:45.377915 2014] [:error] [pid 5679] /usr/local/lib/python2.7/dist-packages/sorl/thumbnail/helpers.py:5: DeprecationWarning: django.utils.simplejson is deprecated; use json instead.
[Wed Jun 25 03:28:45.377981 2014] [:error] [pid 5679]   from django.utils import simplejson
[Wed Jun 25 03:28:45.377986 2014] [:error] [pid 5679] 
[Wed Jun 25 03:28:46.262605 2014] [:error] [pid 5678] /usr/local/lib/python2.7/dist-packages/sorl/thumbnail/helpers.py:5: DeprecationWarning: django.utils.simplejson is deprecated; use json instead.
[Wed Jun 25 03:28:46.262677 2014] [:error] [pid 5678]   from django.utils import simplejson
[Wed Jun 25 03:28:46.262682 2014] [:error] [pid 5678] 
[Wed Jun 25 03:31:48.882292 2014] [:error] [pid 5814] /usr/local/lib/python2.7/dist-packages/sorl/thumbnail/helpers.py:5: DeprecationWarning: django.utils.simplejson is deprecated; use json instead.
[Wed Jun 25 03:31:48.882355 2014] [:error] [pid 5814]   from django.utils import simplejson
[Wed Jun 25 03:31:48.882360 2014] [:error] [pid 5814] 
[Wed Jun 25 03:31:50.076395 2014] [:error] [pid 5815] /usr/local/lib/python2.7/dist-packages/sorl/thumbnail/helpers.py:5: DeprecationWarning: django.utils.simplejson is deprecated; use json instead.
[Wed Jun 25 03:31:50.076458 2014] [:error] [pid 5815]   from django.utils import simplejson
[Wed Jun 25 03:31:50.076463 2014] [:error] [pid 5815] 
[Wed Jun 25 03:35:10.783403 2014] [:error] [pid 5956] /usr/local/lib/python2.7/dist-packages/sorl/thumbnail/helpers.py:5: DeprecationWarning: django.utils.simplejson is deprecated; use json instead.
[Wed Jun 25 03:35:10.783465 2014] [:error] [pid 5956]   from django.utils import simplejson
[Wed Jun 25 03:35:10.783471 2014] [:error] [pid 5956] 
[Wed Jun 25 03:35:11.964377 2014] [:error] [pid 5955] /usr/local/lib/python2.7/dist-packages/sorl/thumbnail/helpers.py:5: DeprecationWarning: django.utils.simplejson is deprecated; use json instead.
[Wed Jun 25 03:35:11.964428 2014] [:error] [pid 5955]   from django.utils import simplejson
[Wed Jun 25 03:35:11.964434 2014] [:error] [pid 5955] 
[Wed Jun 25 03:39:29.651158 2014] [:error] [pid 6101] /usr/local/lib/python2.7/dist-packages/sorl/thumbnail/helpers.py:5: DeprecationWarning: django.utils.simplejson is deprecated; use json instead.
[Wed Jun 25 03:39:29.651227 2014] [:error] [pid 6101]   from django.utils import simplejson
[Wed Jun 25 03:39:29.651233 2014] [:error] [pid 6101] 
[Wed Jun 25 03:40:17.694803 2014] [:error] [pid 6247] /usr/local/lib/python2.7/dist-packages/sorl/thumbnail/helpers.py:5: DeprecationWarning: django.utils.simplejson is deprecated; use json instead.
[Wed Jun 25 03:40:17.694865 2014] [:error] [pid 6247]   from django.utils import simplejson
[Wed Jun 25 03:40:17.694871 2014] [:error] [pid 6247] 
[Wed Jun 25 03:40:18.975654 2014] [:error] [pid 6246] /usr/local/lib/python2.7/dist-packages/sorl/thumbnail/helpers.py:5: DeprecationWarning: django.utils.simplejson is deprecated; use json instead.
[Wed Jun 25 03:40:18.975716 2014] [:error] [pid 6246]   from django.utils import simplejson
[Wed Jun 25 03:40:18.975721 2014] [:error] [pid 6246] 
[Wed Jun 25 03:42:28.686290 2014] [:error] [pid 6382] /usr/local/lib/python2.7/dist-packages/sorl/thumbnail/helpers.py:5: DeprecationWarning: django.utils.simplejson is deprecated; use json instead.
[Wed Jun 25 03:42:28.686356 2014] [:error] [pid 6382]   from django.utils import simplejson
[Wed Jun 25 03:42:28.686362 2014] [:error] [pid 6382] 
[Wed Jun 25 03:42:29.969870 2014] [:error] [pid 6381] /usr/local/lib/python2.7/dist-packages/sorl/thumbnail/helpers.py:5: DeprecationWarning: django.utils.simplejson is deprecated; use json instead.
[Wed Jun 25 03:42:29.969925 2014] [:error] [pid 6381]   from django.utils import simplejson
[Wed Jun 25 03:42:29.969930 2014] [:error] [pid 6381] 
[Wed Jun 25 03:43:39.778720 2014] [:error] [pid 6516] /usr/local/lib/python2.7/dist-packages/sorl/thumbnail/helpers.py:5: DeprecationWarning: django.utils.simplejson is deprecated; use json instead.
[Wed Jun 25 03:43:39.778783 2014] [:error] [pid 6516]   from django.utils import simplejson
[Wed Jun 25 03:43:39.778789 2014] [:error] [pid 6516] 
[Wed Jun 25 03:43:40.679758 2014] [:error] [pid 6515] /usr/local/lib/python2.7/dist-packages/sorl/thumbnail/helpers.py:5: DeprecationWarning: django.utils.simplejson is deprecated; use json instead.
[Wed Jun 25 03:43:40.679812 2014] [:error] [pid 6515]   from django.utils import simplejson
[Wed Jun 25 03:43:40.679818 2014] [:error] [pid 6515] 
[Wed Jun 25 03:50:40.450799 2014] [:error] [pid 6650] /usr/local/lib/python2.7/dist-packages/sorl/thumbnail/helpers.py:5: DeprecationWarning: django.utils.simplejson is deprecated; use json instead.
[Wed Jun 25 03:50:40.450880 2014] [:error] [pid 6650]   from django.utils import simplejson
[Wed Jun 25 03:50:40.450891 2014] [:error] [pid 6650] 
[Wed Jun 25 03:50:41.561790 2014] [:error] [pid 6649] /usr/local/lib/python2.7/dist-packages/sorl/thumbnail/helpers.py:5: DeprecationWarning: django.utils.simplejson is deprecated; use json instead.
[Wed Jun 25 03:50:41.561847 2014] [:error] [pid 6649]   from django.utils import simplejson
[Wed Jun 25 03:50:41.561852 2014] [:error] [pid 6649] 
[Wed Jun 25 03:52:07.260509 2014] [:error] [pid 6785] /usr/local/lib/python2.7/dist-packages/sorl/thumbnail/helpers.py:5: DeprecationWarning: django.utils.simplejson is deprecated; use json instead.
[Wed Jun 25 03:52:07.260562 2014] [:error] [pid 6785]   from django.utils import simplejson
[Wed Jun 25 03:52:07.260567 2014] [:error] [pid 6785] 
[Wed Jun 25 03:52:08.450806 2014] [:error] [pid 6784] /usr/local/lib/python2.7/dist-packages/sorl/thumbnail/helpers.py:5: DeprecationWarning: django.utils.simplejson is deprecated; use json instead.
[Wed Jun 25 03:52:08.450866 2014] [:error] [pid 6784]   from django.utils import simplejson
[Wed Jun 25 03:52:08.450877 2014] [:error] [pid 6784] 
[Wed Jun 25 03:56:28.261585 2014] [:error] [pid 6920] /usr/local/lib/python2.7/dist-packages/sorl/thumbnail/helpers.py:5: DeprecationWarning: django.utils.simplejson is deprecated; use json instead.
[Wed Jun 25 03:56:28.261650 2014] [:error] [pid 6920]   from django.utils import simplejson
[Wed Jun 25 03:56:28.261656 2014] [:error] [pid 6920] 
[Wed Jun 25 03:56:30.045469 2014] [:error] [pid 6919] /usr/local/lib/python2.7/dist-packages/sorl/thumbnail/helpers.py:5: DeprecationWarning: django.utils.simplejson is deprecated; use json instead.
[Wed Jun 25 03:56:30.045533 2014] [:error] [pid 6919]   from django.utils import simplejson
[Wed Jun 25 03:56:30.045543 2014] [:error] [pid 6919] 
[Wed Jun 25 03:59:21.972713 2014] [:error] [pid 7054] /usr/local/lib/python2.7/dist-packages/sorl/thumbnail/helpers.py:5: DeprecationWarning: django.utils.simplejson is deprecated; use json instead.
[Wed Jun 25 03:59:21.972782 2014] [:error] [pid 7054]   from django.utils import simplejson
[Wed Jun 25 03:59:21.972787 2014] [:error] [pid 7054] 
[Wed Jun 25 03:59:22.984050 2014] [:error] [pid 7053] /usr/local/lib/python2.7/dist-packages/sorl/thumbnail/helpers.py:5: DeprecationWarning: django.utils.simplejson is deprecated; use json instead.
[Wed Jun 25 03:59:22.984108 2014] [:error] [pid 7053]   from django.utils import simplejson
[Wed Jun 25 03:59:22.984114 2014] [:error] [pid 7053] 
[Wed Jun 25 04:03:41.174514 2014] [:error] [pid 7189] /usr/local/lib/python2.7/dist-packages/sorl/thumbnail/helpers.py:5: DeprecationWarning: django.utils.simplejson is deprecated; use json instead.
[Wed Jun 25 04:03:41.174569 2014] [:error] [pid 7189]   from django.utils import simplejson
[Wed Jun 25 04:03:41.174575 2014] [:error] [pid 7189] 
[Wed Jun 25 04:03:42.346146 2014] [:error] [pid 7188] /usr/local/lib/python2.7/dist-packages/sorl/thumbnail/helpers.py:5: DeprecationWarning: django.utils.simplejson is deprecated; use json instead.
[Wed Jun 25 04:03:42.346198 2014] [:error] [pid 7188]   from django.utils import simplejson
[Wed Jun 25 04:03:42.346204 2014] [:error] [pid 7188] 
